Workbook

Sheet IS
B1: FY23 | C1: FY24 | D1: FY25 | E1: FY26 | F1: FY27 | G1: FY28 | H1: FY29 | I1: FY30
A2: Interest Income | B2: 1615855367 | C2: 2583405755 | D2: 3005170417 | E2: =D2*(1+Assumptions!$B$2) -> 3.3819897e+09 | F2: =E2*(1+Assumptions!$B$2) -> 3.8060584e+09 | G2: =F2*(1+Assumptions!$B$2) -> 4.2833012e+09 | H2: =G2*(1+Assumptions!$B$2) -> 4.8203857e+09 | I2: =H2*(1+Assumptions!$B$2) -> 5.4248153e+09 | K2: next round no
A3: Other Income | B3: 312148251 | C3: 492409994 | D3: 456322818 | E3: =D3*(1+Assumptions!$B$2) -> 5.1354128e+08 | F3: =E3*(1+Assumptions!$B$2) -> 5.7793438e+08 | G3: =F3*(1+Assumptions!$B$2) -> 6.5040175e+08 | H3: =G3*(1+Assumptions!$B$2) -> 7.3195582e+08 | I3: =H3*(1+Assumptions!$B$2) -> 8.2373599e+08 | K3: provisiosns have tax included
A4: Total Revenue | B4: 1928003618 | C4: 3075815749 | D4: 3461493235 | E4: =SUM(E2:E3) -> 3.8955309e+09 | F4: =SUM(F2:F3) -> 4.3839928e+09 | G4: =SUM(G2:G3) -> 4.933703e+09 | H4: =SUM(H2:H3) -> 5.5523415e+09 | I4: =SUM(I2:I3) -> 6.2485513e+09 | K4: 2023 values are pre merger
A5: Operating Expenses | B5: 476520844 | C5: 633860240 | D5: 681748820 | E5: =E4*(Assumptions!$B$4) -> 7.6723351e+08 | F5: =F4*(Assumptions!$B$4) -> 8.6343716e+08 | G5: =G4*(Assumptions!$B$4) -> 9.7170381e+08 | H5: =H4*(Assumptions!$B$4) -> 1.0935461e+09 | I5: =I4*(Assumptions!$B$4) -> 1.2306661e+09
A6: Interest Expenses | B6: 747433173 | C6: 1498081008 | D6: 1778469527 | E6: =D6*(1+Assumptions!$B$2) -> 2.0014724e+09 | F6: =E6*(1+Assumptions!$B$2) -> 2.2524376e+09 | G6: =F6*(1+Assumptions!$B$2) -> 2.5348715e+09 | H6: =G6*(1+Assumptions!$B$2) -> 2.8527198e+09 | I6: =H6*(1+Assumptions!$B$2) -> 3.2104232e+09 | K6: all values from statements
A7: Provisions (includes tax) | B7: 262962587 | C7: 335751716 | D7: 327801307 | E7: =D7*(1+Assumptions!$B$2) -> 3.6890441e+08 | F7: =E7*(1+Assumptions!$B$2) -> 4.1516145e+08 | G7: =F7*(1+Assumptions!$B$2) -> 4.6721868e+08 | H7: =G7*(1+Assumptions!$B$2) -> 5.2580337e+08 | I7: =H7*(1+Assumptions!$B$2) -> 5.9173402e+08
A8: Total Expenses | B8: 1486916604 | C8: 2467692964 | D8: 2788019654 | E8: =SUM(E5:E7) -> 3.1376103e+09 | F8: =SUM(F5:F7) -> 3.5310362e+09 | G8: =SUM(G5:G7) -> 3.9737939e+09 | H8: =SUM(H5:H7) -> 4.4720692e+09 | I8: =SUM(I5:I7) -> 5.0328233e+09 | K8: Operating Expenses = Total Revenue(cy) × Cost-to-Income ratio,
A9: Profit before Tax | B9: =SUM(B10:B11) -> 584853014 | C9: =SUM(C10:C11) -> 708952985 | D9: =SUM(D10:D11) -> 884780581 | E9: =E4-E8 -> 7.5792064e+08 | F9: =F4-F8 -> 8.5295654e+08 | G9: =G4-G8 -> 9.5990903e+08 | H9: =H4-H8 -> 1.0802723e+09 | I9: =I4-I8 -> 1.215728e+09
A10: Tax | B10: 143766000 | C10: 100830200 | D10: 211307000 | E10: =E9*Assumptions!$B$5 -> 1.8100978e+08 | F10: =F9*Assumptions!$B$5 -> 2.0370665e+08 | G10: =G9*Assumptions!$B$5 -> 2.2924949e+08 | H10: =H9*Assumptions!$B$5 -> 2.5799515e+08 | I10: =I9*Assumptions!$B$5 -> 2.9034525e+08
A11: Profit after Tax (PAT) | B11: 441087014 | C11: 608122785 | D11: 673473581 | E11: =E9-E10 -> 5.7691086e+08 | F11: =F9-F10 -> 6.4924989e+08 | G11: =G9-G10 -> 7.3065954e+08 | H11: =H9-H10 -> 8.2227716e+08 | I11: =I9-I10 -> 9.2538275e+08
K12: note - Operating Expenses are modeled as a function of the Cost-to-Income ratio, while other expense lines are grown at the overall revenue growth rate - this produces slightly different expense dynamics in early projection years
A13: Net Interest income | B13: =B2-B6 -> 868422194 | C13: =C2-C6 -> 1085324747 | D13: =D2-D6 -> 1226700890 | E13: =E2-E6 -> 1.3805173e+09 | F13: =F2-F6 -> 1.5536208e+09 | G13: =G2-G6 -> 1.7484298e+09 | H13: =H2-H6 -> 1.9676659e+09 | I13: =I2-I6 -> 2.2143922e+09
A15: FY25 ROE | B15: =D11/BS!D13 -> 0.13554752

Sheet BS
B1: FY23 | C1: FY24 | D1: FY25 | E1: FY26 | F1: FY27 | G1: FY28 | H1: FY29 | I1: FY30
A2: ASSETS
A3: Cash & Balances with RBI | B3: 1171607706 | C3: 1786832228 | D3: 1443550296 | E3: =E18-(E4+E5+E6+E7+E8) -> 1.9346225e+09 | F3: =F18-(F4+F5+F6+F7+F8) -> 2.4836003e+09 | G3: =G18-(G4+G5+G6+G7+G8) -> 3.0975454e+09 | H3: =H18-(H4+H5+H6+H7+H8) -> 3.7843943e+09 | I3: =I18-(I4+I5+I6+I7+I8) -> 4.5530673e+09 | J3: BS cash
A4: Balances with banks and money at call and short notice | B4: 766043125 | C4: 404641953 | D4: 952156416 | E4: 952156416 | F4: 952156416 | G4: 952156416 | H4: 952156416 | I4: 952156416
A5: Investments | B5: 5170014280 | C5: 7024149587 | D5: 8363596736 | E5: 8363596736 | F5: 8363596736 | G5: 8363596736 | H5: 8363596736 | I5: 8363596736
A6: Advances | B6: 16005859000 | C6: 24848615188 | D6: 26196086171 | E6: =D6+D6*Assumptions!$B$6 -> 2.7616627e+10 | F6: =E6+E6*Assumptions!$B$6 -> 2.9114199e+10 | G6: =F6+F6*Assumptions!$B$6 -> 3.0692981e+10 | H6: =G6+G6*Assumptions!$B$6 -> 3.2357376e+10 | I6: =H6+H6*Assumptions!$B$6 -> 3.4112026e+10
A7: Fixed Assets | B7: 80165410 | C7: 113989878 | D7: 136553987 | E7: 136553987 | F7: 136553987 | G7: 136553987 | H7: 136553987 | I7: 136553987
A8: Other Assets | B8: 1467125151 | C8: 1998002035 | D8: 2010045840 | E8: 2010045840 | F8: 2010045840 | G8: 2010045840 | H8: 2010045840 | I8: 2010045840
A9: Total Assets | B9: 24660814672 | C9: 36176230869 | D9: 39101989446 | E9: =SUM(E3:E8) -> 4.1013602e+10 | F9: =SUM(F3:F8) -> 4.3060153e+10 | G9: =SUM(G3:G8) -> 4.5252879e+10 | H9: =SUM(H3:H8) -> 4.7604123e+10 | I9: =SUM(I3:I8) -> 5.0127446e+10
A10: LIABILITIES
A11: Capital | B11: 5579743 | C11: 7596911 | D11: 7652222 | E11: 7652222 | F11: 7652222 | G11: 7652222 | H11: 7652222 | I11: 7652222
A12: ESOP Outstanding | B12: 10670189 | C12: 26527161 | D12: 38051944 | E12: 38051944 | F12: 38051944 | G12: 38051944 | H12: 38051944 | I12: 38051944
A13: Reserves & Surplus | B13: 2785740145 | C13: 4368333979 | D13: 4968542229 | E13: =D13 + IS!E11*(1-Assumptions!$B$8) -> 5.408041e+09 | F13: =E13 + IS!F11*(1-Assumptions!$B$8) -> 5.9026486e+09 | G13: =F13 + IS!G11*(1-Assumptions!$B$8) -> 6.4592752e+09 | H13: =G13 + IS!H11*(1-Assumptions!$B$8) -> 7.0856974e+09 | I13: =H13 + IS!I11*(1-Assumptions!$B$8) -> 7.7906669e+09
A14: Current Year PAT (included already in R/S) | B14: =IS!B11 -> 441087014 | C14: =IS!C11 -> 608122785 | D14: =IS!D11 -> 673473581 | E14: =IS!E11 -> 5.7691086e+08 | F14: =IS!F11 -> 6.4924989e+08 | G14: =IS!G11 -> 7.3065954e+08 | H14: =IS!H11 -> 8.2227716e+08 | I14: =IS!I11 -> 9.2538275e+08
A15: Deposits | B15: 18833946463 | C15: 23797862764 | D15: 27147148959 | E15: =E6/Assumptions!$B$7 -> 2.8619263e+10 | F15: =F6/Assumptions!$B$7 -> 3.0171206e+10 | G15: =G6/Assumptions!$B$7 -> 3.1807306e+10 | H15: =H6/Assumptions!$B$7 -> 3.3532127e+10 | I15: =I6/Assumptions!$B$7 -> 3.5350481e+10
A16: Borrowings | B16: 2067655655 | C16: 6621530751 | D16: 5479308926 | E16: 5479308926 | F16: 5479308926 | G16: 5479308926 | H16: 5479308926 | I16: 5479308926
A17: Other Liabilities | B17: 957222477 | C17: 1354379303 | D17: 1461285166 | E17: 1461285166 | F17: 1461285166 | G17: 1461285166 | H17: 1461285166 | I17: 1461285166
A18: Total Liabilities | B18: 24660814672 | C18: 36176230869 | D18: 39101989446 | E18: =SUM(E11:E13,E15:E17) -> 4.1013602e+10 | F18: =SUM(F11:F13,F15:F17) -> 4.3060153e+10 | G18: =SUM(G11:G13,G15:G17) -> 4.5252879e+10 | H18: =SUM(H11:H13,H15:H17) -> 4.7604123e+10 | I18: =SUM(I11:I13,I15:I17) -> 5.0127446e+10
A20: Check row (TA-TL=0) | B20: =B9-B18 -> 0 | C20: =C9-C18 -> 0 | D20: =D9-D18 -> 0 | E20: =E9-E18 -> 0 | F20: =F9-F18 -> 0 | G20: =G9-G18 -> 0 | H20: =H9-H18 -> 0 | I20: =I9-I18 -> 0
A21: CHECK - BS CASH = CFS CLOSING CASH | B21: =B3+B4-CFS!B12 -> 0 | C21: =C3+C4-CFS!C12 -> 0 | D21: =D3+D4-CFS!D12 -> 0 | E21: =E3+E4-CFS!E12 -> 2.6147395e+08 | F21: =F3+F4-CFS!F12 -> 5.5230712e+08 | G21: =G3+G4-CFS!G12 -> 8.7598184e+08 | H21: =H3+H4-CFS!H12 -> 4.7365508e+09 | I21: =I3+I4-CFS!I12 -> 5.5052237e+09
J22: advances grow based on loan growth rate and deposits are advances / cd ratio | K22: Note: For FY26-28 (projected years), BS Cash & Balances with RBI is calculated as a balancing plug to ensure Total Assets = Total Liabilities, while CFS Closing Cash is independently projected using simplified growth assumptions on Operating/Investing/Financing activities. As a result, these two figures will not tie out exactly in projected years - unlike FY23-25, where both reflect actual reported figures and match precisely
A24: TOTAL SH. HOLDERS EQUITY | D24: =D13+D11 -> 4976194451 | E24: =E13+E11 -> 5.4156932e+09 | F24: =F13+F11 -> 5.9103008e+09 | G24: =G13+G11 -> 6.4669274e+09 | H24: =H13+H11 -> 7.0933496e+09 | I24: =I13+I11 -> 7.7983191e+09 | J24: R&s= (PY) R&S+PAT(cy)
A25: AVG EQUITY | E25: =(D24+E24)/2 -> 5.1959438e+09 | F25: =(E24+F24)/2 -> 5.662997e+09 | G25: =(F24+G24)/2 -> 6.1886141e+09 | H25: =(G24+H24)/2 -> 6.7801385e+09 | I25: =(H24+I24)/2 -> 7.4458344e+09
J26: cash balances is balancing figure in future years

Sheet CFS
B1: FY23 | C1: FY24 | D1: FY25 | E1: FY26 | F1: FY27 | G1: FY28
A2: Net Profit (already included in totals) | B2: =IS!B11 -> 441087014 | C2: =IS!C11 -> 608122785 | D2: =IS!D11 -> 673473581 | E2: =IS!E11 -> 5.7691086e+08 | F2: =IS!F11 -> 6.4924989e+08 | G2: =IS!G11 -> 7.3065954e+08
A4: Cash Flow from Operating Activities | B4: 273134078 | C4: 350149646 | D4: 1451773037 | E4: =D4*(1+Assumptions!$B$2) -> 1.6338113e+09 | F4: =E4*(1+Assumptions!$B$2) -> 1.8386754e+09 | G4: =F4*(1+Assumptions!$B$2) -> 2.0692275e+09
A5: Cash Flow from Investing Activities | B5: -24288813 | C5: 70941730 | D5: -20390054 | E5: =D5*(1+Assumptions!$B$2) -> -22946769 | F5: =E5*(1+Assumptions!$B$2) -> -25824072 | G5: =F5*(1+Assumptions!$B$2) -> -29062160
A6: Cash Flow from Financing Activities | B6: 161219226 | C6: -222369351 | D6: -1229088782 | E6: =D6*(1+Assumptions!$B$2) -> -1.3832046e+09 | F6: =E6*(1+Assumptions!$B$2) -> -1.5566451e+09 | G6: =F6*(1+Assumptions!$B$2) -> -1.7518333e+09
A7: Effect of fluctuation in foreign currency translation reserve | B7: 4317096 | C7: 1012629 | D7: 1938330 | E7: 1938330 | F7: 1938330 | G7: 1938330
A9: Net Increase/Decrease in Cash | B9: =SUM(B4:B7) -> 414381587 | C9: =SUM(C4:C7) -> 199734654 | D9: =SUM(D4:D7) -> 204232531 | E9: =SUM(E4:E7) -> 2.2959826e+08 | F9: =SUM(F4:F7) -> 2.5814461e+08 | G9: =SUM(G4:G7) -> 2.902704e+08
A10: Cash acquired on amalagamation | B10: 0 | C10: 54088696 | D10: 0 | E10: 0 | F10: 0 | G10: 0
A11: Opening Cash Balance | B11: 1523269244 | C11: 1937650831 | D11: 2191474181 | E11: =D12 -> 2395706712 | F11: =E12 -> 2.625305e+09 | G11: =F12 -> 2.8834496e+09
A12: Closing Cash Balance | B12: =SUM(B9:B11) -> 1937650831 | C12: =SUM(C9:C11) -> 2191474181 | D12: =SUM(D9:D11) -> 2395706712 | E12: =SUM(E9:E11) -> 2.625305e+09 | F12: =SUM(F9:F11) -> 2.8834496e+09 | G12: =SUM(G9:G11) -> 3.17372e+09
A14: CHECK
A15: Check (Closing Cash per report) | B15: 1937650831 | C15: 2191474181 | D15: 2395706712
A16: Difference (should be 0, "TRUE") | B16: =B15-B12=0 -> TRUE | C16: =C15-C12=0 -> TRUE | D16: =D15-D12=0 -> TRUE
A18: cash flows assumed to be grown at rev growth %

Sheet Assumptions
B1: In % 2025
A2: Revenue Growth % | B2: =(IS!D4/IS!C4)-1 -> 0.12539031
A3: NIM % (Net Interest Margin) | B3: =IS!D13/BS!D6 -> 0.04682764
A4: Cost to Income % | B4: =IS!D5/IS!D4 -> 0.19695223
A5: Tax Rate % | B5: =IS!D10/IS!D9 -> 0.23882418
A6: Loan Growth% | B6: =(BS!D6/BS!C6)-1 -> 0.054227206 | H6: For Dividend payout ratio
A7: Credit-Deposit Ratio | B7: =BS!D6/BS!D15 -> 0.96496638 | C7: =adv/deposits | H7: fy 25 | I7: fy24
A8: Dividend Payout ratio (didvidend per shares/earnings per share - basic) | B8: =AVERAGE(H8:I8) -> 0.23818607 | H8: =22/88.29 -> 0.24917884 | I8: =19.5/85.83 -> 0.22719329
A9: SANITY CHECK | D9: FY26 | E9: FY27 | F9: FY28 | G9: FY29 | H9: FY30
A10: RATIOS
A11: Return on Equity = Net Profit (PAT) ÷ Avg Equity | D11: =IS!E11/BS!E25 -> 0.111031 | E11: =IS!F11/BS!F13 -> 0.10999298 | F11: =IS!G11/BS!G13 -> 0.11311788 | G11: =IS!H11/BS!H13 -> 0.11604746 | H11: =IS!I11/BS!I13 -> 0.11878094
A12: NIM = Net Interest Income ÷ Advances | D12: =IS!E13/BS!E6 -> 0.049988628 | E12: =IS!F13/BS!F6 -> 0.053362992 | F12: =IS!G13/BS!G6 -> 0.056965134 | G12: =IS!H13/BS!H6 -> 0.06081043 | H12: =IS!I13/BS!I6 -> 0.064915294
A13: Cost to income ratio | D13: =IS!E5/IS!E4 -> 0.19695223 | E13: =IS!F5/IS!F4 -> 0.19695223 | F13: =IS!G5/IS!G4 -> 0.19695223 | G13: =IS!H5/IS!H4 -> 0.19695223 | H13: =IS!I5/IS!I4 -> 0.19695223
A14: Sustainable Growth Rate (ROE x Retention Ratio) | B14: 0.08 | D14: =D11*(1-$B$8) -> 0.084584967 | E14: =E11*(1-$B$8) -> 0.083794183 | F14: =F11*(1-$B$8) -> 0.08617478 | G14: =G11*(1-$B$8) -> 0.08840657 | H14: =H11*(1-$B$8) -> 0.090488977
A16: retention ratio = 100% - CD Ratio | B16: =100%-B8 -> 0.76181393
B23: fy24 and fy25 compariosn is more compatible as fy23 is pre merger values | E23: NIM= net int income / advances | G23: Cost to income = op exp / total rev | I23: ROE (Return on Equity): 11.10% to 11.00% to 11.31% to 11.60% to 11.88%
I25: Lower than HDFC Bank's typical 15-18% range, mainly due to the HDFC Ltd merger (completed July 2023), which increased the equity base. Profit is still catching up, so lower ROE is expected. Small dip in FY27 (11.10% to 11.00%) happens because equity grew slightly faster than profit that year.
I27: NIM (Net Interest Margin): 5.00% → 5.34% → 5.70% → 6.08% → 6.49% Calculated as Net Interest Income divided by Advances. Slightly higher than the typical 3.5-4.5% range for Indian banks, but reasonable for a well-performing bank like HDFC. NIM rises steadily each year as Interest Income grows faster than Advances, reflecting improving yields as the bank scales post-merger.

Sheet DCF
B1: FY26 | C1: FY27 | D1: FY28 | E1: FY29 | F1: FY30
A2: Net Income | B2: =IS!E11 -> 5.7691086e+08 | C2: =IS!F11 -> 6.4924989e+08 | D2: =IS!G11 -> 7.3065954e+08 | E2: =IS!H11 -> 8.2227716e+08 | F2: =IS!I11 -> 9.2538275e+08
A3: Equity Reinvestments (R&S(py)-R&S(cy)) | B3: =BS!E13-BS!D13 -> 4.3949873e+08 | C3: =BS!F13-BS!E13 -> 4.9460762e+08 | D3: =BS!G13-BS!F13 -> 5.5662662e+08 | E3: =BS!H13-BS!G13 -> 6.264222e+08 | F3: =BS!I13-BS!H13 -> 7.0496947e+08
A4: FCFE (Free Cash Flow to Equity) | B4: =B2-B3 -> 1.3741213e+08 | C4: =C2-C3 -> 1.5464228e+08 | D4: =D2-D3 -> 1.7403292e+08 | E4: =E2-E3 -> 1.9585496e+08 | F4: =F2-F3 -> 2.2041328e+08
A5: Years away | B5: 1 | C5: 2 | D5: 3 | E5: 4 | F5: 5
A6: Discounted FCFE | B6: =B4/(1+$B$12)^B5 -> 1.2029426e+08 | C6: =C4/(1+$B$12)^C5 -> 1.1851352e+08 | D6: =D4/(1+$B$12)^D5 -> 1.1675914e+08 | E6: =E4/(1+$B$12)^E5 -> 1.1503073e+08 | F6: =F4/(1+$B$12)^F5 -> 1.1332791e+08
A8: Risk-Free Rate | B8: 0.0685
A9: Beta | B9: 1.23
A10: Equity Risk Premium | B10: 0.06
A12: Cost of Equity = Risk-Free Rate + Beta × Equity Risk Premium | B12: =B8+B9*B10 -> 0.1423
A14: Terminal Growth Rate (=here, sustainale growth rate) | B14: =Assumptions!B14 -> 0.08
A16: Terminal Value = FY30 FCFE × 1.08 ÷ (Cost of Equity − 8%) | F16: =F4*(1+B14)/(B12-B14) -> 3.8209685e+09
A17: (from fy31 onwards)
A18: Discounted Terminal Value | F18: =F16/(1+$B$12)^5 -> 1.9645929e+09
A20: Equity Value | B20: =SUM(B6:F6)+F18 -> 2.5485185e+09
A21: Shares Outstanding | B21: 15403717 | C21: (1230757 cr mkt cap / 799 (current MP)
A22: Intrinsic Value per share | B22: =B20/B21 -> 165.44828
A24: EXCESS RETURN METHOD | B24: FY26 | C24: FY27 | D24: FY28 | E24: FY29 | F24: FY30
A25: Beginning Book Value | B25: =BS!D13 -> 4968542229 | C25: =BS!E13 -> 5.408041e+09 | D25: =BS!F13 -> 5.9026486e+09 | E25: =BS!G13 -> 6.4592752e+09 | F25: =BS!H13 -> 7.0856974e+09
A26: Net Income | B26: =IS!E11 -> 5.7691086e+08 | C26: =IS!F11 -> 6.4924989e+08 | D26: =IS!G11 -> 7.3065954e+08 | E26: =IS!H11 -> 8.2227716e+08 | F26: =IS!I11 -> 9.2538275e+08
A27: Required Return (CoE × Beg. BV) | B27: =$B$12*B25 -> 7.0702356e+08 | C27: =$B$12*C25 -> 7.6956423e+08 | D27: =$B$12*D25 -> 8.3994689e+08 | E27: =$B$12*E25 -> 9.1915486e+08 | F27: =$B$12*F25 -> 1.0082947e+09
A28: Excess Return | B28: =B26-B27 -> -1.301127e+08 | C28: =C26-C27 -> -1.2031434e+08 | D28: =D26-D27 -> -1.0928735e+08 | E28: =E26-E27 -> -96877697 | F28: =F26-F27 -> -82911989
A29: Discounted Excess Return | B29: =B28/(1+$B$12)^B5 -> -1.1390414e+08 | C29: =C28/(1+$B$12)^C5 -> -92205541 | D29: =D28/(1+$B$12)^D5 -> -73321169 | E29: =E28/(1+$B$12)^E5 -> -56898799 | F29: =F28/(1+$B$12)^F5 -> -42630110
A31: Terminal Value (Excess Return) | F31: =F28*(1+Assumptions!F14)/($B$12-Assumptions!F14) -> -1.6045712e+09
A32: Disc terminal value (excess return) | F32: =F31/(1+$B$12)^5 -> -8.250079e+08
A34: Current Book Value (FY25) | B34: =BS!D13 -> 4968542229
A35: Sum of Discounted Excess Returns | B35: =SUM(B29:F29) -> -3.7895976e+08
A36: Total Equity Value (Excess Return Method) | B36: =B34+B35+F32 -> 3.7645746e+09
A38: Intrinsic Value per Share | B38: =B36/B21 -> 244.39391
A39: Upside/Downside -DOWNSIDE | B39: =(B38/799)-1 -> -0.69412527
A43: Sensitivity Analysis — Excess Return Intrinsic Value per Share (₹)
A44: CoE ↓ / Terminal Growth Rate → | B44: =B38 -> 244.39391 | C44: 0.05 | D44: 0.065 | E44: 0.08 | F44: 0.095 | G44: 0.11
A45: Cost of Equity | B45: 0.11 | C45: =IFERROR(($B$34+$B$35+(($F$28*(1+C$44))/(INDIRECT("B"&ROW())-C$44))/(1+INDIRECT("B"&ROW()))^5)/$B$21,"N/A") -> 242.05252 | D45: =IFERROR(($B$34+$B$35+(($F$28*(1+D$44))/(INDIRECT("B"&ROW())-D$44))/(1+INDIRECT("B"&ROW()))^5)/$B$21,"N/A") -> 222.35428 | E45: =IFERROR(($B$34+$B$35+(($F$28*(1+E$44))/(INDIRECT("B"&ROW())-E$44))/(1+INDIRECT("B"&ROW()))^5)/$B$21,"N/A") -> 182.9578 | F45: =IFERROR(($B$34+$B$35+(($F$28*(1+F$44))/(INDIRECT("B"&ROW())-F$44))/(1+INDIRECT("B"&ROW()))^5)/$B$21,"N/A") -> 64.768373 | G45: =IFERROR(($B$34+$B$35+(($F$28*(1+G$44))/(INDIRECT("B"&ROW())-G$44))/(1+INDIRECT("B"&ROW()))^5)/$B$21,"N/A") -> N/A | I45: N/A as Terminal Growth Rate cannot exceed Cost of Equity
B46: 0.125 | C46: =IFERROR(($B$34+$B$35+(($F$28*(1+C$44))/(INDIRECT("B"&ROW())-C$44))/(1+INDIRECT("B"&ROW()))^5)/$B$21,"N/A") -> 256.1355 | D46: =IFERROR(($B$34+$B$35+(($F$28*(1+D$44))/(INDIRECT("B"&ROW())-D$44))/(1+INDIRECT("B"&ROW()))^5)/$B$21,"N/A") -> 244.93441 | E46: =IFERROR(($B$34+$B$35+(($F$28*(1+E$44))/(INDIRECT("B"&ROW())-E$44))/(1+INDIRECT("B"&ROW()))^5)/$B$21,"N/A") -> 226.26592 | F46: =IFERROR(($B$34+$B$35+(($F$28*(1+F$44))/(INDIRECT("B"&ROW())-F$44))/(1+INDIRECT("B"&ROW()))^5)/$B$21,"N/A") -> 188.92894 | G46: =IFERROR(($B$34+$B$35+(($F$28*(1+G$44))/(INDIRECT("B"&ROW())-G$44))/(1+INDIRECT("B"&ROW()))^5)/$B$21,"N/A") -> 76.917991
B47: 0.1423 | C47: =IFERROR(($B$34+$B$35+(($F$28*(1+C$44))/(INDIRECT("B"&ROW())-C$44))/(1+INDIRECT("B"&ROW()))^5)/$B$21,"N/A") -> 266.46975 | D47: =IFERROR(($B$34+$B$35+(($F$28*(1+D$44))/(INDIRECT("B"&ROW())-D$44))/(1+INDIRECT("B"&ROW()))^5)/$B$21,"N/A") -> 259.82343 | E47: =IFERROR(($B$34+$B$35+(($F$28*(1+E$44))/(INDIRECT("B"&ROW())-E$44))/(1+INDIRECT("B"&ROW()))^5)/$B$21,"N/A") -> 249.97663 | F47: =IFERROR(($B$34+$B$35+(($F$28*(1+F$44))/(INDIRECT("B"&ROW())-F$44))/(1+INDIRECT("B"&ROW()))^5)/$B$21,"N/A") -> 233.88452 | G47: =IFERROR(($B$34+$B$35+(($F$28*(1+G$44))/(INDIRECT("B"&ROW())-G$44))/(1+INDIRECT("B"&ROW()))^5)/$B$21,"N/A") -> 202.84616
B48: 0.16 | C48: =IFERROR(($B$34+$B$35+(($F$28*(1+C$44))/(INDIRECT("B"&ROW())-C$44))/(1+INDIRECT("B"&ROW()))^5)/$B$21,"N/A") -> 273.49055 | D48: =IFERROR(($B$34+$B$35+(($F$28*(1+D$44))/(INDIRECT("B"&ROW())-D$44))/(1+INDIRECT("B"&ROW()))^5)/$B$21,"N/A") -> 269.22343 | E48: =IFERROR(($B$34+$B$35+(($F$28*(1+E$44))/(INDIRECT("B"&ROW())-E$44))/(1+INDIRECT("B"&ROW()))^5)/$B$21,"N/A") -> 263.35615 | F48: =IFERROR(($B$34+$B$35+(($F$28*(1+F$44))/(INDIRECT("B"&ROW())-F$44))/(1+INDIRECT("B"&ROW()))^5)/$B$21,"N/A") -> 254.78088 | G48: =IFERROR(($B$34+$B$35+(($F$28*(1+G$44))/(INDIRECT("B"&ROW())-G$44))/(1+INDIRECT("B"&ROW()))^5)/$B$21,"N/A") -> 241.06045
B49: 0.175 | C49: =IFERROR(($B$34+$B$35+(($F$28*(1+C$44))/(INDIRECT("B"&ROW())-C$44))/(1+INDIRECT("B"&ROW()))^5)/$B$21,"N/A") -> 277.76546 | D49: =IFERROR(($B$34+$B$35+(($F$28*(1+D$44))/(INDIRECT("B"&ROW())-D$44))/(1+INDIRECT("B"&ROW()))^5)/$B$21,"N/A") -> 274.6849 | E49: =IFERROR(($B$34+$B$35+(($F$28*(1+E$44))/(INDIRECT("B"&ROW())-E$44))/(1+INDIRECT("B"&ROW()))^5)/$B$21,"N/A") -> 270.63154 | F49: =IFERROR(($B$34+$B$35+(($F$28*(1+F$44))/(INDIRECT("B"&ROW())-F$44))/(1+INDIRECT("B"&ROW()))^5)/$B$21,"N/A") -> 265.05817 | G49: =IFERROR(($B$34+$B$35+(($F$28*(1+G$44))/(INDIRECT("B"&ROW())-G$44))/(1+INDIRECT("B"&ROW()))^5)/$B$21,"N/A") -> 256.91247
A51: Market Price: ₹799
A52: Base Case (CoE 14.23%, g 8%): ₹244
A53: All cells red = stock appears overvalued across all assumption combinations
...

Sheet WM
A1: Company Snapshot | D1: Valuation Summary
A2: Company Name | B2: HDFC Bank Ltd | D2: Method | E2: Intrinsic Value | F2: vs Market Value | G2: Upside/Downside
A3: Sector | B3: Private Sector Banking, India | D3: FCFE DCF | E3: 165 | F3: 799 | G3: =(E3/F3)-1 -> -0.79349186
A4: Market Price (as of June 2026) | B4: 799 | D4: Excess Return | E4: 244 | F4: 799 | G4: =(E4/F4)-1 -> -0.69461827
A5: Model Date | B5: 29th June 2026
D6: Both methods suggest HDFC Bank is currently trading at a significant premium to intrinsic value.
A8: Key Assumptions
A9: Risk-Free Rate: | B9: 6.85% (India 10Y G-Sec)
A10: Beta: | B10: 1.23 (Moneycontrol)
A11: Equity Risk Premium: | B11: 6% (Damodaran + India CRP)
A12: Cost of Equity: | B12: 0.1423
A13: Terminal Growth Rate: | B13: 8% (ROE × Retention Ratio)
A14: Forecast Period: | B14: FY26–FY30
A16: Investment Recommendation
A17: Recommendation | B17: HOLD / AVOID for value investors at current price. The stock appears richly valued relative to current fundamentals. A re-rating would require meaningful ROE recovery post the HDFC Ltd merger, convergence toward lower cost of equity, or both
A18: Key Risks
A19: NPA Risk: | B19: Rising loan defaults could compress margins and reduce actual ROE below projections | C19: Interest Rate Risk: | D19: RBI rate cuts would compress Net Interest Margin, reducing net interest income | E19: Merger Integration Risk: | F19: Post HDFC Ltd merger, ROE dilution may persist longer than market expects, further widening the gap between intrinsic value and market price

Sheet DCF( confusion)
B1: FY26 | C1: FY27 | D1: FY28 | E1: FY29 | F1: FY30
A2: Net Income | B2: =IS!E11 -> 5.7691086e+08 | C2: =IS!F11 -> 6.4924989e+08 | D2: =IS!G11 -> 7.3065954e+08 | E2: =IS!H11 -> 8.2227716e+08 | F2: =IS!I11 -> 9.2538275e+08
A3: Equity Reinvestments (R&S(py)-R&S(cy)) | B3: =BS!E13-BS!D13 -> 4.3949873e+08 | C3: =BS!F13-BS!E13 -> 4.9460762e+08 | D3: =BS!G13-BS!F13 -> 5.5662662e+08 | E3: =BS!H13-BS!G13 -> 6.264222e+08 | F3: =BS!I13-BS!H13 -> 7.0496947e+08
A4: FCFE (Free Cash Flow to Equity) | B4: =B2-B3 -> 1.3741213e+08 | C4: =C2-C3 -> 1.5464228e+08 | D4: =D2-D3 -> 1.7403292e+08 | E4: =E2-E3 -> 1.9585496e+08 | F4: =F2-F3 -> 2.2041328e+08
A5: Years away | B5: 1 | C5: 2 | D5: 3 | E5: 4 | F5: 5
A6: Discounted FCFE | B6: =B4/(1+$B$12)^B5 -> 1.2476699e+08 | C6: =C4/(1+$B$12)^C5 -> 1.2749041e+08 | D6: =D4/(1+$B$12)^D5 -> 1.3027328e+08 | E6: =E4/(1+$B$12)^E5 -> 1.3311689e+08 | F6: =F4/(1+$B$12)^F5 -> 1.3602257e+08
A8: Risk-Free Rate | B8: 0.07
A9: Beta | B9: 0.75
A10: Equity Risk Premium | B10: 0.0418
A12: Cost of Equity = Risk-Free Rate + Beta × Equity Risk Premium | B12: =B8+B9*B10 -> 0.10135
A14: Terminal Growth Rate (=here, sustainale growth rate) | B14: =Assumptions!B14 -> 0.08
A16: Terminal Value = FY30 FCFE × 1.055 ÷ (Cost of Equity − 5.5%) | F16: =F4*(1+B14)/(B12-B14) -> 1.1149711e+10
A17: (from fy31 onwards)
A18: Discounted Terminal Value | F18: =F16/(1+$B$12)^5 -> 6.8807669e+09
A20: Equity Value | B20: =SUM(B6:F6)+F18 -> 7.5324371e+09
A21: Shares Outstanding | B21: 15403717 | C21: (1230757 cr mkt cap / 799 (current MP) | G21: 5.5% = an assumption we picked, representing a reasonable long-term growth rate for India's economy (and by extension, HDFC Bank)
A22: Intrinsic Value per share | B22: =B20/B21 -> 489.00126 | G22: 1.055 = simply 5.5% rewritten in multiplication form (1 + the percentage), used to project FY30's cash flow one more year forward into FY31
A24: EXCESS RETURN METHOD | B24: FY26 | C24: FY27 | D24: FY28 | E24: FY29 | F24: FY30
A25: Beginning Book Value | B25: =BS!D13 -> 4968542229 | C25: =BS!E13 -> 5.408041e+09 | D25: =BS!F13 -> 5.9026486e+09 | E25: =BS!G13 -> 6.4592752e+09 | F25: =BS!H13 -> 7.0856974e+09
A26: Net Income | B26: =IS!E11 -> 5.7691086e+08 | C26: =IS!F11 -> 6.4924989e+08 | D26: =IS!G11 -> 7.3065954e+08 | E26: =IS!H11 -> 8.2227716e+08 | F26: =IS!I11 -> 9.2538275e+08
A27: Required Return (CoE × Beg. BV) | B27: =$B$12*B25 -> 5.0356175e+08 | C27: =$B$12*C25 -> 5.4810495e+08 | D27: =$B$12*D25 -> 5.9823343e+08 | E27: =$B$12*E25 -> 6.5464754e+08 | F27: =$B$12*F25 -> 7.1813543e+08
A28: Excess Return | B28: =B26-B27 -> 73349108 | C28: =C26-C27 -> 1.0114494e+08 | D28: =D26-D27 -> 1.324261e+08 | E28: =E26-E27 -> 1.6762962e+08 | F28: =F26-F27 -> 2.0724732e+08
A29: Discounted Excess Return | B29: =B28/(1+$B$12)^B5 -> 66599272 | C29: =C28/(1+$B$12)^C5 -> 83386061 | D29: =D28/(1+$B$12)^D5 -> 99128272 | E29: =E28/(1+$B$12)^E5 -> 1.1393295e+08 | F29: =F28/(1+$B$12)^F5 -> 1.2789753e+08
A31: Terminal Value (Excess Return) | F31: =F28*(1+Assumptions!F14)/($B$12-Assumptions!F14) -> 1.4833842e+10
A32: Disc terminal value (excess return) | F32: =F31/(1+$B$12)^5 -> 9.1543361e+09
A34: Current Book Value (FY25) | B34: =BS!D13 -> 4968542229
A35: Sum of Discounted Excess Returns | B35: =SUM(B29:F29) -> 4.9094408e+08
A36: Total Equity Value (Excess Return Method) | B36: =B34+B35+F32 -> 1.4613822e+10
A38: Intrinsic Value per Share | B38: =B36/B21 -> 948.72052
A39: Upside/Downside - UPSIDE | B39: =(B38/799)-1 -> 0.18738488
A41: Terminal Growth Rate across columns

Sheet Comps
B1: P/E | C1: P/BV | D1: ROE% | E1: NIM% | F1: nim from perfomace review reports and rest from screener
A2: HDFC Bank | B2: 16.2 | C2: 2.1 | D2: 0.138 | E2: 0.0338
A3: ICICI Bank | B3: 18.4 | C3: 2.8 | D3: 0.161 | E3: 0.0432
A4: Kotak Mahindra Bank | B4: 20.7 | C4: 2.2 | D4: 0.112 | E4: 0.0467
A5: Axis Bank | B5: 16 | C5: 2 | D5: 0.131 | E5: 0.0362
A6: Peer Average (excl. HDFC) | B6: =AVERAGE(B3:B5) -> 18.366667 | C6: =AVERAGE(C3:C5) -> 2.3333333 | D6: =AVERAGE(D3:D5) -> 0.13466667 | E6: =AVERAGE(E3:E5) -> 0.042033333
F8: HDFC Bank trades at a P/E of 16.2 and a P/BV of 2.1, which are both lower than the peer averages of 18.37 and 2.33, meaning the market is currently valuing HDFC cheaper than ICICI, Kotak, and Axis | H8: This supports my DCF finding. Both approaches point the same way - my DCF says HDFC's true value is lower than its current market price, and the Comps table shows the market itself is already valuing HDFC lower than similar banks. Together, this suggests the discount is likely linked to post-merger integration challenges affecting margins
F9: This discount likely comes from HDFC's NIM (3.38%) trailing the peer average (4.20%), even though HDFC's ROE (13.80%) is actually slightly better than the peer average (13.47%) - so the gap seems driven by margin pressure, not overall profitability.
